<?xml version="1.0" ?>
<!-- =================================================================================== -->
<!-- |    This document was autogenerated by xacro from src/rr1_description/urdf/rr1.urdf.xacro | -->
<!-- |    EDITING THIS FILE BY HAND IS NOT RECOMMENDED                                 | -->
<!-- =================================================================================== -->
<robot name="rr1">
  <!-- Namespace -->
  <!-- Specify some standard inertial calculations
    https://en.wikipedia.org/wiki/List_of_moments_of_inertia -->
  <!-- Gazebo's ros2_control plugin -->
  <gazebo>
    <plugin filename="libgazebo_ros2_control.so" name="gazebo_ros2_control">
      <robot_sim_type>gazebo_ros2_control/GazeboSystem</robot_sim_type>
      <parameters>/home/envilon/dev_ws/install/rr1_description/share/rr1_description/config/rr1_controller.yaml</parameters>
      <ros>
        <namespace>/rr1</namespace>
        <remapping>/tf:=/rr1/tf</remapping>
      </ros>
    </plugin>
  </gazebo>
  <ros2_control name="GazeboSystem" type="system">
    <hardware>
      <plugin>gazebo_ros2_control/GazeboSystem</plugin>
    </hardware>
    <joint name="shoulder_joint">
      <command_interface name="position">
        <param name="min">-2.3561944901925003</param>
        <param name="max">2.3561944901925003</param>
      </command_interface>
      <state_interface name="position">
        <param name="initial_value">0.0</param>
      </state_interface>
      <state_interface name="velocity">
        <param name="initial_value">0.0</param>
      </state_interface>
      <state_interface name="effort">
        <param name="initial_value">0.0</param>
      </state_interface>
    </joint>
    <joint name="upper_arm_joint">
      <command_interface name="position">
        <param name="min">-0.39269908169875</param>
        <param name="max">0.39269908169875</param>
      </command_interface>
      <state_interface name="position">
        <param name="initial_value">0.0</param>
      </state_interface>
      <state_interface name="velocity">
        <param name="initial_value">0.0</param>
      </state_interface>
      <state_interface name="effort">
        <param name="initial_value">0.0</param>
      </state_interface>
    </joint>
    <joint name="elbow_joint">
      <command_interface name="position">
        <param name="min">-1.570796326795</param>
        <param name="max">1.570796326795</param>
      </command_interface>
      <state_interface name="position">
        <param name="initial_value">0.0</param>
      </state_interface>
      <state_interface name="velocity">
        <param name="initial_value">0.0</param>
      </state_interface>
      <state_interface name="effort">
        <param name="initial_value">0.0</param>
      </state_interface>
    </joint>
    <joint name="forearm_joint">
      <command_interface name="position">
        <param name="min">-2.3561944901925003</param>
        <param name="max">2.3561944901925003</param>
      </command_interface>
      <state_interface name="position">
        <param name="initial_value">0.0</param>
      </state_interface>
      <state_interface name="velocity">
        <param name="initial_value">0.0</param>
      </state_interface>
      <state_interface name="effort">
        <param name="initial_value">0.0</param>
      </state_interface>
    </joint>
    <joint name="wrist_joint">
      <command_interface name="position">
        <param name="min">0</param>
        <param name="max">3.14159265359</param>
      </command_interface>
      <state_interface name="position">
        <param name="initial_value">0.0</param>
      </state_interface>
      <state_interface name="velocity">
        <param name="initial_value">0.0</param>
      </state_interface>
      <state_interface name="effort">
        <param name="initial_value">0.0</param>
      </state_interface>
    </joint>
    <joint name="hand_joint">
      <command_interface name="position">
        <param name="min">-2.3561944901925003</param>
        <param name="max">2.3561944901925003</param>
      </command_interface>
      <state_interface name="position">
        <param name="initial_value">0.0</param>
      </state_interface>
      <state_interface name="velocity">
        <param name="initial_value">0.0</param>
      </state_interface>
      <state_interface name="effort">
        <param name="initial_value">0.0</param>
      </state_interface>
    </joint>
    <joint name="finger_joint">
      <command_interface name="position">
        <param name="min">0</param>
        <param name="max">1.1780972450962501</param>
      </command_interface>
      <state_interface name="position">
        <param name="initial_value">0.0</param>
      </state_interface>
      <state_interface name="velocity">
        <param name="initial_value">0.0</param>
      </state_interface>
      <state_interface name="effort">
        <param name="initial_value">0.0</param>
      </state_interface>
    </joint>
    <joint name="opposite_finger_joint">
      <command_interface name="position">
        <param name="min">0</param>
        <param name="max">1.1780972450962501</param>
      </command_interface>
      <state_interface name="position">
        <param name="initial_value">0.0</param>
      </state_interface>
      <state_interface name="velocity">
        <param name="initial_value">0.0</param>
      </state_interface>
      <state_interface name="effort">
        <param name="initial_value">0.0</param>
      </state_interface>
    </joint>
  </ros2_control>
  <!-- We need a world link because we want the base link of the robot to be anchored to it -->
  <link name="world"/>
  <!-- Create a link with a given name. -->
  <link name="base_link">
    <!-- Create a visual component using a provided mesh file -->
    <visual>
      <origin rpy="0 0 0" xyz="-0.052 -0.013 0.179"/>
      <geometry>
        <mesh filename="package://rr1_description/mesh/visual/01_RR1_extended_base.dae" scale="0.001 0.001 0.001"/>
      </geometry>
    </visual>
    <!-- Create a collision component using a provided mesh file -->
    <collision>
      <origin rpy="0 0 0" xyz="-0.052 -0.013 0.179"/>
      <geometry>
        <mesh filename="package://rr1_description/mesh/collision/01_RR1_extended_base.stl" scale="0.001 0.001 0.001"/>
      </geometry>
    </collision>
    <!-- Insert provided inertial block -->
    <inertial>
      <origin rpy="0 0 0" xyz="0.105 0 0.0375"/>
      <mass value="4.0"/>
      <inertia ixx="0.010199999999999999" ixy="0.0" ixz="0.0" iyy="0.045899999999999996" iyz="0.0" izz="0.050699999999999995"/>
    </inertial>
  </link>
  <joint name="virtual_joint" type="fixed">
    <parent link="world"/>
    <child link="base_link"/>
    <origin xyz="0 0 0"/>
  </joint>
  <!-- Create a link with a given name. -->
  <link name="shoulder_link">
    <!-- Create a visual component using a provided mesh file -->
    <visual>
      <origin rpy="0 0 0" xyz="-0.052 -0.013 0.109"/>
      <geometry>
        <mesh filename="package://rr1_description/mesh/visual/02_RR1_shoulder.dae" scale="0.001 0.001 0.001"/>
      </geometry>
    </visual>
    <!-- Create a collision component using a provided mesh file -->
    <collision>
      <origin rpy="0 0 0" xyz="-0.052 -0.013 0.109"/>
      <geometry>
        <mesh filename="package://rr1_description/mesh/collision/02_RR1_shoulder.stl" scale="0.001 0.001 0.001"/>
      </geometry>
    </collision>
    <!-- Insert provided inertial block -->
    <inertial>
      <origin rpy="0 -0.39269908169875 0" xyz="-0.04 -0.035 0.0545"/>
      <mass value="2.5"/>
      <inertia ixx="0.008312499999999999" ixy="0.0" ixz="0.0" iyy="0.008312499999999999" iyz="0.0" izz="0.003125"/>
    </inertial>
  </link>
  <joint name="shoulder_joint" type="revolute">
    <parent link="base_link"/>
    <child link="shoulder_link"/>
    <origin xyz="0 0 0.07"/>
    <axis xyz="0 0 1"/>
    <limit effort="30" lower="-2.3561944901925003" upper="2.3561944901925003" velocity="7.853985"/>
    <dynamics damping="10" friction="10.0"/>
  </joint>
  <!-- Create a link with a given name. -->
  <link name="upper_arm_link">
    <!-- Create a visual component using a provided mesh file -->
    <visual>
      <origin rpy="0 0 0" xyz="0 -0.013 0"/>
      <geometry>
        <mesh filename="package://rr1_description/mesh/visual/03_RR1_upper_arm.dae" scale="0.001 0.001 0.001"/>
      </geometry>
    </visual>
    <!-- Create a collision component using a provided mesh file -->
    <collision>
      <origin rpy="0 0 0" xyz="0 -0.013 0"/>
      <geometry>
        <mesh filename="package://rr1_description/mesh/collision/03_RR1_upper_arm.stl" scale="0.001 0.001 0.001"/>
      </geometry>
    </collision>
    <!-- Insert provided inertial block -->
    <inertial>
      <origin rpy="0 0 0" xyz="0 0.035 0.125"/>
      <mass value="2.5"/>
      <inertia ixx="0.02584895833333333" ixy="0.0" ixz="0.0" iyy="0.02584895833333333" iyz="0.0" izz="0.009031250000000001"/>
    </inertial>
  </link>
  <joint name="upper_arm_joint" type="revolute">
    <parent link="shoulder_link"/>
    <child link="upper_arm_link"/>
    <origin xyz="-0.052 0 0.109"/>
    <axis xyz="0 1 0"/>
    <limit effort="30" lower="-0.39269908169875" upper="0.39269908169875" velocity="7.853985"/>
    <dynamics damping="10" friction="10.0"/>
  </joint>
  <!-- Create a link with a given name. -->
  <link name="elbow_link">
    <!-- Create a visual component using a provided mesh file -->
    <visual>
      <origin rpy="0 0 0" xyz="0 -0.013 -0.225"/>
      <geometry>
        <mesh filename="package://rr1_description/mesh/visual/04_RR1_elbow.dae" scale="0.001 0.001 0.001"/>
      </geometry>
    </visual>
    <!-- Create a collision component using a provided mesh file -->
    <collision>
      <origin rpy="0 0 0" xyz="0 -0.013 -0.225"/>
      <geometry>
        <mesh filename="package://rr1_description/mesh/collision/04_RR1_elbow.stl" scale="0.001 0.001 0.001"/>
      </geometry>
    </collision>
    <!-- Insert provided inertial block -->
    <inertial>
      <origin rpy="0 0 0" xyz="0.032 0 0.04"/>
      <mass value="1.75"/>
      <inertia ixx="0.005705729166666666" ixy="0.0" ixz="0.0" iyy="0.00967983333333333" iyz="0.0" izz="0.004856395833333332"/>
    </inertial>
  </link>
  <joint name="elbow_joint" type="revolute">
    <parent link="upper_arm_link"/>
    <child link="elbow_link"/>
    <origin xyz="0 0 0.225"/>
    <axis xyz="0 1 0"/>
    <limit effort="30" lower="-1.570796326795" upper="1.570796326795" velocity="7.853985"/>
    <dynamics damping="10" friction="10.0"/>
  </joint>
  <!-- Create a link with a given name. -->
  <link name="forearm_link">
    <!-- Create a visual component using a provided mesh file -->
    <visual>
      <origin rpy="0 0 0" xyz="0 -0.0042 -0.3257"/>
      <geometry>
        <mesh filename="package://rr1_description/mesh/visual/05_RR1_forearm.dae" scale="0.001 0.001 0.001"/>
      </geometry>
    </visual>
    <!-- Create a collision component using a provided mesh file -->
    <collision>
      <origin rpy="0 0 0" xyz="0 -0.0042 -0.3257"/>
      <geometry>
        <mesh filename="package://rr1_description/mesh/collision/05_RR1_forearm.stl" scale="0.001 0.001 0.001"/>
      </geometry>
    </collision>
    <!-- Insert provided inertial block -->
    <inertial>
      <origin rpy="0 -1.570796326795 0" xyz="-0.18 0 0"/>
      <mass value="1.5"/>
      <inertia ixx="0.009387500000000002" ixy="0.0" ixz="0.0" iyy="0.009387500000000002" iyz="0.0" izz="0.0018750000000000004"/>
    </inertial>
  </link>
  <joint name="forearm_joint" type="revolute">
    <parent link="elbow_link"/>
    <child link="forearm_link"/>
    <origin xyz="0 -0.0088 0.1007"/>
    <axis xyz="1 0 0"/>
    <limit effort="30" lower="-2.3561944901925003" upper="2.3561944901925003" velocity="7.853985"/>
    <dynamics damping="10" friction="10.0"/>
  </joint>
  <!-- Create a link with a given name. -->
  <link name="wrist_link">
    <!-- Create a visual component using a provided mesh file -->
    <visual>
      <origin rpy="0 0 0" xyz="0.284 -0.0042 -0.3257"/>
      <geometry>
        <mesh filename="package://rr1_description/mesh/visual/06_RR1_wrist.dae" scale="0.001 0.001 0.001"/>
      </geometry>
    </visual>
    <!-- Create a collision component using a provided mesh file -->
    <collision>
      <origin rpy="0 0 0" xyz="0.284 -0.0042 -0.3257"/>
      <geometry>
        <mesh filename="package://rr1_description/mesh/collision/06_RR1_wrist.stl" scale="0.001 0.001 0.001"/>
      </geometry>
    </collision>
    <!-- Insert provided inertial block -->
    <inertial>
      <origin rpy="0 0 0" xyz="0 0.062 0.038"/>
      <mass value="1.0"/>
      <inertia ixx="0.0011696666666666665" ixy="0.0" ixz="0.0" iyy="0.0011696666666666665" iyz="0.0" izz="0.00032266666666666663"/>
    </inertial>
  </link>
  <joint name="wrist_joint" type="revolute">
    <parent link="forearm_link"/>
    <child link="wrist_link"/>
    <origin xyz="-0.284 0 0"/>
    <axis xyz="0 1 0"/>
    <limit effort="30" lower="0" upper="3.14159265359" velocity="7.853985"/>
    <dynamics damping="10" friction="10.0"/>
  </joint>
  <!-- Create a link with a given name. -->
  <link name="hand_link">
    <!-- Create a visual component using a provided mesh file -->
    <visual>
      <origin rpy="0 0 0" xyz="0.284 -0.07 -0.3257"/>
      <geometry>
        <mesh filename="package://rr1_description/mesh/visual/07_RR1_hand_no_grip.dae" scale="0.001 0.001 0.001"/>
      </geometry>
    </visual>
    <!-- Create a collision component using a provided mesh file -->
    <collision>
      <origin rpy="0 0 0" xyz="0.284 -0.07 -0.3257"/>
      <geometry>
        <mesh filename="package://rr1_description/mesh/collision/07_RR1_hand_no_grip.stl" scale="0.001 0.001 0.001"/>
      </geometry>
    </collision>
    <!-- Insert provided inertial block -->
    <inertial>
      <origin rpy="0 0 0" xyz="0 0 -0.08"/>
      <mass value="0.5"/>
      <inertia ixx="0.0009924479166666667" ixy="0.0" ixz="0.0" iyy="0.0009924479166666667" iyz="0.0" izz="0.0003515625"/>
    </inertial>
  </link>
  <joint name="hand_joint" type="revolute">
    <parent link="wrist_link"/>
    <child link="hand_link"/>
    <origin xyz="0 0.0658 0"/>
    <axis xyz="0 0 1"/>
    <limit effort="30" lower="-2.3561944901925003" upper="2.3561944901925003" velocity="7.853985"/>
    <dynamics damping="10" friction="10.0"/>
  </joint>
  <!-- Create a link with a given name. -->
  <link name="finger_link">
    <!-- Create a visual component using a provided mesh file -->
    <visual>
      <origin rpy="0 0 0" xyz="0.274 -0.07 -0.1757"/>
      <geometry>
        <mesh filename="package://rr1_description/mesh/visual/08_RR1_grip.dae" scale="0.001 0.001 0.001"/>
      </geometry>
    </visual>
    <!-- Create a collision component using a provided mesh file -->
    <collision>
      <origin rpy="0 0 0" xyz="0.274 -0.07 -0.1757"/>
      <geometry>
        <mesh filename="package://rr1_description/mesh/collision/08_RR1_grip.stl" scale="0.001 0.001 0.001"/>
      </geometry>
    </collision>
    <!-- Insert provided inertial block -->
    <inertial>
      <origin rpy="0 0 0" xyz="0.01 0 -0.05"/>
      <mass value="0.25"/>
      <inertia ixx="8.333333333333333e-05" ixy="0.0" ixz="0.0" iyy="7.708333333333333e-05" iyz="0.0" izz="1.0416666666666666e-05"/>
    </inertial>
  </link>
  <joint name="finger_joint" type="revolute">
    <parent link="hand_link"/>
    <child link="finger_link"/>
    <origin xyz="0.01 0 -0.15"/>
    <axis xyz="0 -1 0"/>
    <limit effort="30" lower="0" upper="1.1780972450962501" velocity="7.853985"/>
    <dynamics damping="10" friction="10.0"/>
  </joint>
  <!-- Create a link with a given name. -->
  <link name="opposite_finger_link">
    <!-- Create a visual component using a provided mesh file -->
    <visual>
      <origin rpy="0 0 0" xyz="0.294 -0.07 -0.1757"/>
      <geometry>
        <mesh filename="package://rr1_description/mesh/visual/08_RR1_grip_opposite.dae" scale="0.001 0.001 0.001"/>
      </geometry>
    </visual>
    <!-- Create a collision component using a provided mesh file -->
    <collision>
      <origin rpy="0 0 0" xyz="0.294 -0.07 -0.1757"/>
      <geometry>
        <mesh filename="package://rr1_description/mesh/collision/08_RR1_grip_opposite.stl" scale="0.001 0.001 0.001"/>
      </geometry>
    </collision>
    <!-- Insert provided inertial block -->
    <inertial>
      <origin rpy="0 0 0" xyz="-0.01 0 -0.05"/>
      <mass value="0.25"/>
      <inertia ixx="8.333333333333333e-05" ixy="0.0" ixz="0.0" iyy="7.708333333333333e-05" iyz="0.0" izz="1.0416666666666666e-05"/>
    </inertial>
  </link>
  <joint name="opposite_finger_joint" type="revolute">
    <parent link="hand_link"/>
    <child link="opposite_finger_link"/>
    <origin xyz="-0.01 0 -0.15"/>
    <axis xyz="0 1 0"/>
    <mimic joint="finger_joint"/>
    <limit effort="30" lower="0" upper="1.1780972450962501" velocity="7.853985"/>
    <dynamics damping="10" friction="10.0"/>
  </joint>
  <link name="tool"/>
  <joint name="tool_joint" type="fixed">
    <parent link="hand_link"/>
    <child link="tool"/>
    <origin xyz="0 0 -0.195"/>
  </joint>
</robot>
